Workbook

Sheet HD0. Trang chủ
A1: ITTs SOP TEMP
A2: Sheet tổng quan vận hành. Số liệu tự cập nhật.
A4: PRE-SALES (Phase 1-4)
A5: Tổng lead | C5: Lead mới chưa LH | E5: Đã đăng ký | G5: Doanh thu đã thu
A6: =COUNTA('DL02. Khách tiềm năng'!A4:A500) -> 20 | C6: =COUNTIF('DL02. Khách tiềm năng'!P4:P500,"new*") -> 2 | E6: =COUNTIF('DL06. Đăng ký'!F4:F500,"confirmed*") -> 14 | G6: =SUM('DL07. Thanh toán'!H4:H500) -> 218000000
A7: Tất cả lead | C7: =HYPERLINK("#'CH2. Tham số & Quy tắc'!A"&MATCH("slaLRT_minutes",'CH2. Tham số & Quy tắc'!$A:$A,0),"SLA gọi "&slaLRT_minutes&" phút") -> SLA gọi 15 phút | E7: Đăng ký đã xác nhận | G7: Tiền thực nhận
A8: VẬN HÀNH HỌC (Phase 5-10)
A9: HV đang học | C9: HV nguy cơ | E9: Lớp đang chạy | G9: Khiếu nại chưa xử lý
A10: =COUNTIF('DL09. Học viên'!O4:O500,"active*") -> 11 | C10: =COUNTIF('DL09. Học viên'!R4:R500,"at_risk*")+COUNTIF('DL09. Học viên'!R4:R500,"off_track*")+COUNTIF('DL09. Học viên'!S4:S500,"at_risk*")+COUNTIF('DL09. Học viên'!S4:S500,"off_track*") -> 4 | E10: =COUNTIF('DL10. Lớp học'!K4:K500,"in_progress*") -> 4 | G10: =COUNTIF('DL17. Khiếu nại'!J4:J500,"new*")+COUNTIF('DL17. Khiếu nại'!J4:J500,"assigned*")+COUNTIF('DL17. Khiếu nại'!J4:J500,"in_progress*")+COUNTIF('DL17. Khiếu nại'!J4:J500,"escalated*") -> 4
A11: HV đang học | C11: 2 trục, cần can thiệp | E11: Lớp đang chạy | G11: Khiếu nại đang mở
A12: VIỆC CẦN LÀM HÔM NAY
A13: Task sheet | B13: Nội dung | C13: Số lượng | D13: Mở
A14: VH5. Lead cần liên hệ lại | B14: Lead cần liên hệ | C14: =COUNTIF('DL02. Khách tiềm năng'!Q4:Q500,"<="&TODAY()+1) -> 3 | D14: =HYPERLINK("#'VH5. Việc - Chăm khách'!A1","Mở") -> Mở
A15: VH6. HV nguy cơ | B15: HV cần can thiệp | C15: =COUNTIF('DL09. Học viên'!R4:R500,"at_risk*")+COUNTIF('DL09. Học viên'!R4:R500,"off_track*") -> 2 | D15: =HYPERLINK("#'VH6. Việc - Học viên nguy cơ'!A1","Mở") -> Mở
A16: VH7. Test chờ chấm | B16: Test chưa có kết quả | C16: =COUNTIF('DL03. Đặt lịch test'!J4:J500,"pending*") -> 1 | D16: =HYPERLINK("#'VH7. Việc - Test chờ chấm'!A1","Mở") -> Mở
A17: VH8. Học phí đến hạn | B17: Học phí chờ thu | C17: =COUNTIF('DL06. Đăng ký'!P4:P500,"partial*")+COUNTIF('DL06. Đăng ký'!P4:P500,"unpaid*") -> 4 | D17: =HYPERLINK("#'VH8. Việc - Thu học phí'!A1","Mở") -> Mở
A18: VH9. Lớp sắp khai giảng | B18: =HYPERLINK("#'CH2. Tham số & Quy tắc'!A"&MATCH("thresholdClassStart_days",'CH2. Tham số & Quy tắc'!$A:$A,0),"Lớp khai giảng trong "&thresholdClassStart_days&" ngày") -> Lớp khai giảng trong 14 ngày | C18: =COUNTIFS('DL10. Lớp học'!F4:F500,">="&TODAY(),'DL10. Lớp học'!F4:F500,"<="&TODAY()+thresholdClassStart_days) -> 2 | D18: =HYPERLINK("#'VH9. Việc - Lớp sắp khai giảng'!A1","Mở") -> Mở
A19: VH10. Khiếu nại chưa xử lý | B19: Khiếu nại đang mở | C19: =COUNTIF('DL17. Khiếu nại'!J4:J500,"<>resolved*")-COUNTBLANK('DL17. Khiếu nại'!J4:J500) -> 4 | D19: =HYPERLINK("#'VH10. Việc - Khiếu nại'!A1","Mở") -> Mở
A21: ĐIỀU HƯỚNG NHANH
A22: Cấu hình | B22: =HYPERLINK("#'CH2. Tham số & Quy tắc'!A1","Tham số hệ thống") -> Tham số hệ thống | C22: =HYPERLINK("#'CH1. Danh mục lựa chọn'!A1","Enum") -> Enum | D22: =HYPERLINK("#'CH3. Phân quyền'!A1","Phân quyền") -> Phân quyền | E22: =HYPERLINK("#'CH6. Ngưỡng KPI'!A1","Ngưỡng KPI") -> Ngưỡng KPI | F22: =HYPERLINK("#'HD3. Sổ trigger & tự động'!A1","Tra cứu thông điệp") -> Tra cứu thông điệp
A23: Nhập liệu | B23: =HYPERLINK("#'DL02. Khách tiềm năng'!A1","Lead") -> Lead | C23: =HYPERLINK("#'DL06. Đăng ký'!A1","Đăng ký") -> Đăng ký | D23: =HYPERLINK("#'DL09. Học viên'!A1","Học viên") -> Học viên | E23: =HYPERLINK("#'DL10. Lớp học'!A1","Lớp") -> Lớp
A24: Báo cáo | B24: =HYPERLINK("#'BC2. Chỉ số KPI'!A1","Chỉ số KPI") -> Chỉ số KPI | C24: =HYPERLINK("#'BC4. Báo cáo tháng'!A1","Tháng") -> Tháng | D24: =HYPERLINK("#'BC1. Học viên nguy cơ'!A1","HV nguy cơ") -> HV nguy cơ | E24: =HYPERLINK("#'BC9. Bảng Quản lý'!A1","Bảng Quản lý") -> Bảng Quản lý
A25: Tra cứu | B25: =HYPERLINK("#'VH2. Tra cứu Học viên'!A1","1 HV") -> 1 HV | C25: =HYPERLINK("#'VH4. Tra cứu Khách tiềm năng'!A1","1 Lead") -> 1 Lead | D25: =HYPERLINK("#'VH1. Tra cứu Lớp'!A1","1 Lớp") -> 1 Lớp
A27: =HYPERLINK("#'VH0. Tìm kiếm'!A1","TÌM KIẾM NHANH (theo tên / SĐT) - bấm vào đây") -> TÌM KIẾM NHANH (theo tên / SĐT) - bấm vào đây

Sheet HD1. Hướng dẫn sử dụng
A1: HƯỚNG DẪN SỬ DỤNG - ITTs SOP TEMP
A2: Hệ thống vận hành trung tâm trên Google Sheets: 52 sheet, 5 nhóm, số hóa trọn quy trình 10 giai đoạn. Trang này là cửa ngõ - đọc 5 phút là dùng được.
A4: 1. BẢN ĐỒ HỆ THỐNG - 5 NHÓM SHEET
B5: Nhóm | C5: Vai trò | D5: Ai dùng | E5: Khi nào | F5: Mở
B6: HD - Hướng dẫn (xám) | C6: Đọc để hiểu và tra cứu cách hệ thống chạy | D6: Mọi người | E6: Khi mới vào / khi thắc mắc | F6: =HYPERLINK("#'HD0. Trang chủ'!A1","HD0") -> HD0
B7: CH - Cấu hình (đỏ) | C7: Mọi danh mục, ngưỡng, thông điệp - sửa 1 chỗ, cả file đổi theo | D7: IT / Quản lý | E7: Khi đổi quy định | F7: =HYPERLINK("#'CH2. Tham số & Quy tắc'!A1","CH2") -> CH2
B8: DL - Dữ liệu (xanh dương) | C8: Nhập và xem chi tiết từng bản ghi (18 sheet + lịch WOW) | D8: Theo vai trò | E8: Khi nhập liệu / dò chi tiết | F8: =HYPERLINK("#'DL02. Khách tiềm năng'!A1","DL02") -> DL02
B9: VH - Vận hành (xanh lá) | C9: Danh sách việc đã lọc sẵn + tra cứu nhanh | D9: Nhân viên | E9: Hằng ngày | F9: =HYPERLINK("#'VH5. Việc - Chăm khách'!A1","VH5") -> VH5
B10: BC - Báo cáo (cam) | C10: Dashboard: KPI, phễu, việc cần duyệt, nguy cơ | D10: Quản lý | E10: Hằng ngày / hằng tuần | F10: =HYPERLINK("#'BC2. Chỉ số KPI'!A1","BC2") -> BC2
A13: 2. CÁCH ĐỌC MỘT SHEET DỮ LIỆU (DL)
B14: Vị trí | C14: Ý nghĩa
B15: Dòng 1 | C15: Tên cột kỹ thuật (tiếng Anh) - dùng cho công thức, KHÔNG sửa.
B16: Dòng 2 | C16: Tên tiếng Việt - giải thích ý nghĩa của biến.
B17: Dòng 3 | C17: Gợi ý nhập nhanh cho cột (nếu có).
B18: Dòng 4 trở đi | C18: Dữ liệu. Mỗi dòng 1 bản ghi, cột A là mã định danh.
B19: Ô chứa mã (HV001, ENR-...) | C19: Có liên kết về dữ liệu gốc.
B20: Cột "next_action" | C20: Câu nhắc tự sinh kèm màu ưu tiên. Tra "vì sao hiện câu này" ở HD3.
A22: 3. CẨM NANG THEO VAI TRÒ - mở đúng sheet của mình
B23: Vai trò | C23: Mở mỗi ngày | D23: Nhập liệu ở | E23: Xem báo cáo | F23: Lối tắt
B24: NV Tư vấn | C24: VH5 (khách cần chăm) | D24: DL02 - DL04, DL06 | E24: BC5, BC3 | F24: =HYPERLINK("#'VH5. Việc - Chăm khách'!A1","VH5") -> VH5
B25: NV Học vụ | C25: VH6, VH9, VH10 | D25: DL08, DL09, DL15 - DL17 | E25: BC8, BC1 | F25: =HYPERLINK("#'VH6. Việc - Học viên nguy cơ'!A1","VH6") -> VH6
B26: Giảng viên | C26: DL11 (buổi của mình) | D26: DL11 - DL13 | E26: BC7 | F26: =HYPERLINK("#'BC7. Bảng Giảng viên'!A1","BC7") -> BC7
B27: NV WOW | C27: VH7 (test chờ chấm) | D27: DL03, DL14 | E27: BC6 | F27: =HYPERLINK("#'VH7. Việc - Test chờ chấm'!A1","VH7") -> VH7
B28: Kế toán | C28: VH8 (thu học phí) | D28: DL07 (+DL06 nhắc nợ) | E28: BC9 (tài chính) | F28: =HYPERLINK("#'VH8. Việc - Thu học phí'!A1","VH8") -> VH8
B29: Quản lý | C29: BC9 (cần duyệt), BC1 | D29: duyệt tại DL06 | E29: BC2, BC4, VH11 | F29: =HYPERLINK("#'BC9. Bảng Quản lý'!A1","BC9") -> BC9
A31: 4. HIỂU FILE QUA VÍ DỤ THẬT - theo chân Trần Minh Anh (HV001)
B32: Xem demo các trang nối nhau bằng mã ID. Quy trình liền mạch cho 1 học viên
B33: Bước | C33: Mở sheet | D33: Tìm mã | E33: Bạn sẽ thấy
B34: 1 | C34: =HYPERLINK("#'DL02. Khách tiềm năng'!A1","DL02. Khách tiềm năng") -> DL02. Khách tiềm năng | D34: L-2026-00006 | E34: Điểm khởi đầu: Trần Minh Anh để lại thông tin, mục tiêu xây nền.
B35: 2 | C35: =HYPERLINK("#'DL03. Đặt lịch test'!A1","DL03. Đặt lịch test") -> DL03. Đặt lịch test | D35: TB-2026-003 | E35: Làm test đầu vào: overall 4.0, đã chấm, đã tư vấn.
B36: 3 | C36: =HYPERLINK("#'DL04. Tư vấn'!A1","DL04. Tư vấn") -> DL04. Tư vấn | D36: CS-2026-002 | E36: Tư vấn theo kết quả test, chốt khóa Foundation kèm cọc.
B37: 4 | C37: =HYPERLINK("#'DL06. Đăng ký'!A1","DL06. Đăng ký") -> DL06. Đăng ký | D37: ENR-2026-001 | E37: Đăng ký khóa. final_fee, paid_amount tự tính.
B38: 5 | C38: =HYPERLINK("#'DL07. Thanh toán'!A1","DL07. Thanh toán") -> DL07. Thanh toán | D38: PAY-2026-001 | E38: Đóng đủ 12.000.000đ một lần, net_received tự trừ phí.
B39: 6 | C39: =HYPERLINK("#'DL09. Học viên'!A1","DL09. Học viên") -> DL09. Học viên | D39: HV001 | E39: Hồ sơ chính thức. Cờ nguy cơ 2 trục đều ổn.
B40: 7 | C40: =HYPERLINK("#'DL08. Xếp lớp & Nhập học'!A1","DL08. Xếp lớp & Nhập học") -> DL08. Xếp lớp & Nhập học | D40: OB-001 | E40: Xếp vào lớp LOP-FOUND-PLA-01, onboarding hoàn tất.
B41: 8 | C41: =HYPERLINK("#'DL10. Lớp học'!A1","DL10. Lớp học") -> DL10. Lớp học | D41: LOP-FOUND-PLA-01 | E41: Lớp Foundation: GV, sĩ số tự đếm từ onboarding.
A44: 5. DANH MỤC ĐẦY ĐỦ 52 SHEET (bấm tên để mở)
B45: NHÓM HƯỚNG DẪN (tab xám)
B46: =HYPERLINK("#'HD0. Trang chủ'!A1","HD0. Trang chủ") -> HD0. Trang chủ | C46: Trang chủ - đếm việc hôm nay + điều hướng nhanh
B47: =HYPERLINK("#'HD1. Hướng dẫn sử dụng'!A1","HD1. Hướng dẫn sử dụng") -> HD1. Hướng dẫn sử dụng | C47: Nhìn tổng quát chức năng các trang
...

Sheet HD2. Quy trình nghiệp vụ
A1: QUY TRÌNH HƯỚNG DẪN TỪNG BƯỚC (SOP TEMP)
A2: File này mô tả toàn bộ quy trình vận hành ITTs theo SOP, chia theo 10 Phase. Mỗi sheet data có cột "next_action" tự gợi ý việc cần làm tiếp.
A3: Cách dùng hằng ngày: mỗi sáng mở dashboard vai trò của mình (nhóm BC màu cam) và các sheet "Việc cần làm" (nhóm VH màu xanh lá) để biết hôm nay phải xử lý gì.
A4: CÁCH ĐỌC BẢNG: Mỗi bảng bên dưới là 1 Phase trong quy trình. Đọc theo từng HÀNG, từ trái sang phải: (1) "Trạng thái hiện tại" của lead/học viên - (2) "Điều kiện" để biết rơi vào trường hợp nào - (3) "Hành động cần làm" - (4) "Người làm" - (5) "SLA" là thời hạn phải xong - (6) "Kết quả / Trạng thái mới": giá trị tiếng Anh (vd contacted, confirmed) chính là giá trị cần nhập vào cột trạng thái ở sheet data tương ứng; sau khi nhập, lead/HV chuyển sang hàng có trạng thái đó để làm bước tiếp theo. Mọi bước cũng được hệ thống tự nhắc ở cột "next_action" trong các sheet VH (Việc cần làm).
A5: LUỒNG TỔNG QUAN - 10 PHASE
A6: Lead vào -> P1 Tiếp nhận -> P2 Test -> P3 Tư vấn+Báo giá -> P4 Thanh toán -> P5 Xếp lớp -> P6 Vận hành buổi -> P7 BT+WOW -> P8 Khảo sát -> P9 Feedback/KN -> P10 Kết thúc khóa
A8: PHASE 1-3: TƯ VẤN - LEAD ENROLL
A9: Trạng thái hiện tại | B9: Điều kiện | C9: Hành động cần làm | D9: Người làm | E9: SLA | F9: Kết quả / Trạng thái mới
A10: lead_status = new (Chưa liên hệ) | B10: Lead vừa vào hệ thống | C10: Gọi điện thoại lần 1 | D10: NV Tư vấn | E10: =HYPERLINK("#'CH2. Tham số & Quy tắc'!A"&MATCH("slaLRT_minutes",'CH2. Tham số & Quy tắc'!$A:$A,0),slaLRT_minutes&" phút") -> 15 phút | F10: contacted (Đã liên hệ)
A11: lead_status = new (Chưa liên hệ) | B11: ="Quá "&slaLRT_minutes&"p chưa gọi" -> Quá 15p chưa gọi | C11: KHẨN: gọi NGAY + ghi nhận lý do trễ | D11: NV Tư vấn + Sale Leader | E11: NGAY | F11: contacted (Đã liên hệ)
A12: lead_status = contacted (Đã liên hệ, đang khai thác) | B12: HV chưa book test | C12: Hẹn ngày làm test đầu vào | D12: NV Tư vấn | E12: =HYPERLINK("#'CH2. Tham số & Quy tắc'!A"&MATCH("slaFollowup_grace_days",'CH2. Tham số & Quy tắc'!$A:$A,0),slaFollowup_grace_days&" ngày") -> 3 ngày | F12: booking_status = booked (đã làm test)
A13: lead_status = contacted (Đã liên hệ, đang khai thác) | B13: ="HV từ chối test sau "&thresholdContacted_attempts&" lần liên hệ" -> HV từ chối test sau 5 lần liên hệ | C13: Đổi lead_status = rejected (Từ chối) | D13: NV Tư vấn | E13: - | F13: lead_status = rejected (Từ chối)
A14: test_status = pending (Chưa có kết quả) | B14: test_result_overall còn trống | C14: NV WOW chấm test + ghi nhận xét | D14: NV WOW Coach | E14: =HYPERLINK("#'CH2. Tham số & Quy tắc'!A"&MATCH("slaGLA_hours",'CH2. Tham số & Quy tắc'!$A:$A,0),slaGLA_hours&" giờ") -> 24 giờ | F14: (điền test_result + academic_note)
A15: test_status = graded (Đã chấm xong) | B15: Đã có test_result | C15: Tư vấn lộ trình + gói khóa phù hợp | D15: NV Tư vấn | E15: =HYPERLINK("#'CH2. Tham số & Quy tắc'!A"&MATCH("slaCVT_hours",'CH2. Tham số & Quy tắc'!$A:$A,0),slaCVT_hours&" giờ") -> 24 giờ | F15: consulted (Đã tư vấn lộ trình)
A16: consultation_status = consulted (Đã tư vấn xong) | B16: quoted_amount còn trống | C16: Gửi báo giá chính thức (email/Zalo) | D16: NV Tư vấn | E16: =HYPERLINK("#'CH2. Tham số & Quy tắc'!A"&MATCH("slaQuote_days",'CH2. Tham số & Quy tắc'!$A:$A,0),slaQuote_days&" ngày") -> 1 ngày | F16: conversion_status = interested (đã báo giá, quan tâm)
A17: consultation_status = consulted (Đã tư vấn xong) | B17: ="Có chiết khấu ≥ "&TEXT(thresholdDiscount_approval,"#,##0")&"đ" -> Có chiết khấu ≥ 1,000,000đ | C17: Xin Trưởng phòng TV hoặc CEO duyệt | D17: NV Tư vấn QL | E17: =HYPERLINK("#'CH2. Tham số & Quy tắc'!A"&MATCH("slaApproval_days",'CH2. Tham số & Quy tắc'!$A:$A,0),slaApproval_days&" ngày") -> 1 ngày | F17: (điền discount_approved_by)
A18: conversion_status = interested (Quan tâm, chưa chốt) | B18: Chưa enroll | C18: Follow-up chốt deal. Nếu sau 3 lần FL không phản hồi thì đổi lead_status = unreachable | D18: NV Tư vấn | E18: =HYPERLINK("#'CH2. Tham số & Quy tắc'!A"&MATCH("thresholdContacted_days",'CH2. Tham số & Quy tắc'!$A:$A,0),thresholdContacted_days&" ngày") -> 7 ngày | F18: enrollment_status = confirmed (Đã xác nhận) / lead_status = rejected (Từ chối)
A19: enrollment_status = confirmed (Đã xác nhận) + payment_status = paid (Đã thanh toán đủ) | B19: Đã đóng tiền | C19: Chuyển sheet "DL07. Thanh toán" + báo Học vụ | D19: NV Tư vấn | E19: NGAY | F19: -> Chuyển sang Phase 4 (xem bảng phía dưới)
A20: lead_status = unreachable (Hết cách liên lạc) | B20: - | C20: Ghi rõ lost_reason để học bài | D20: NV Tư vấn | E20: - | F20: (đóng case)
A22: PHASE 4: THANH TOÁN
A23: Trạng thái | B23: Điều kiện | C23: Hành động | D23: Người làm | E23: SLA | F23: Kết quả / Trạng thái mới
A24: payment_status = unpaid (Chưa thanh toán) | B24: Báo giá xong, chờ chuyển khoản | C24: Gửi link/STK + theo dõi | D24: NV TV | E24: - | F24: completed (Hoàn tất) / partial (Đóng từng đợt)
A25: payment_status = paid (Đã thanh toán đủ) | B25: Đã thu đủ | C25: Lập hóa đơn + xác nhận với HV | D25: Kế toán | E25: =HYPERLINK("#'CH2. Tham số & Quy tắc'!A"&MATCH("slaPaymentConfirm_days",'CH2. Tham số & Quy tắc'!$A:$A,0),slaPaymentConfirm_days&" ngày") -> 1 ngày | F25: -> Chuyển sang Phase 5 (xem bảng phía dưới)
A26: payment_status = partial (Đã thanh toán 1 phần) | B26: Chưa đóng đợt tiếp | C26: FL nhắc HV đợt 2 theo lịch | D26: Kế toán | E26: Theo lịch đợt | F26: completed (Hoàn tất)
A27: payment_status = refunded (Đã hoàn tiền) | B27: HV yêu cầu hoàn | C27: Xác minh + duyệt + lập biên bản | D27: Kế toán + QL | E27: =HYPERLINK("#'CH2. Tham số & Quy tắc'!A"&MATCH("slaRefundProcess_days",'CH2. Tham số & Quy tắc'!$A:$A,0),slaRefundProcess_days&" ngày") -> 5 ngày | F27: (close)
A29: PHASE 5: XẾP LỚP (Học vụ)
A30: Tình huống | B30: Điều kiện | C30: Hành động | D30: Người làm | E30: SLA | F30: Kết quả / Trạng thái mới
A31: placement_status = not_assigned (Chưa xếp lớp) | B31: Chưa có class_id | C31: Tạo bản ghi xếp lớp (sheet DL08) + gán class_id phù hợp band & lịch của HV | D31: Học vụ | E31: =HYPERLINK("#'DL08. Xếp lớp & Nhập học'!A"&MATCH("slaPLR48_hours",'CH2. Tham số & Quy tắc'!$A:$A,0),slaPLR48_hours&" giờ") -> 48 giờ | F31: Có class_id
A32: placement_status = not_assigned (Chưa xếp lớp) + không còn lớp phù hợp (cùng band đều full hoặc lệch lịch) | B32: Lớp cùng band đã full hoặc lịch không khớp | C32: Báo NV TV + đề xuất mở lớp mới hoặc waitlist | D32: Học vụ TP | E32: =HYPERLINK("#'CH2. Tham số & Quy tắc'!A"&MATCH("slaPLR48_hours",'CH2. Tham số & Quy tắc'!$A:$A,0),slaPLR48_hours&" giờ") -> 48 giờ | F32: waitlist / mở lớp
A33: class: current_enrollment = class_capacity (lớp đã đủ sĩ số) | B33: current_enrollment = class_capacity | C33: Khóa enroll thêm hoặc xin duyệt vượt sĩ số | D33: Học vụ TP | E33: NGAY | F33: -
A35: PHASE 6: VẬN HÀNH BUỔI HỌC
A36: Trạng thái buổi | B36: Điều kiện | C36: Hành động | D36: Người làm | E36: SLA | F36: Kết quả / Trạng thái mới
A37: session_status = scheduled (Đã lên lịch) | B37: Buổi sắp diễn ra | C37: Chuẩn bị giáo án + tài liệu | D37: Giảng viên | E37: Trước buổi | F37: in_progress (Đang thực hiện)
A38: session_status = in_progress (Đang diễn ra) | B38: GV đã bấm "Bắt đầu" | C38: Dạy + cập nhật điểm danh sau giờ | D38: Giảng viên | E38: Realtime | F38: completed (Hoàn tất)
A39: session_status = completed (Đã hoàn thành) + teacher_note_completed_at còn trống | B39: has_teacher_note = FALSE | C39: Viết teacher_note 6 phần | D39: Giảng viên | E39: =HYPERLINK("#'CH2. Tham số & Quy tắc'!A"&MATCH("slaTeacherNote_hours",'CH2. Tham số & Quy tắc'!$A:$A,0),slaTeacherNote_hours&" giờ") -> 48 giờ | F39: Ghi: has_teacher_note = TRUE
A40: session_status = completed (Đã hoàn thành) + teacher_note_completed_at đã có | B40: has_teacher_note = TRUE | C40: Học vụ duyệt note + chia sẻ HV | D40: Học vụ | E40: =HYPERLINK("#'CH2. Tham số & Quy tắc'!A"&MATCH("slaNoteReview_hours",'CH2. Tham số & Quy tắc'!$A:$A,0),slaNoteReview_hours&" giờ") -> 24 giờ | F40: Hoàn tất
A41: session_status = cancelled (Đã hủy) | B41: Buổi bị hủy đột xuất | C41: Báo HV + lên lịch bù | D41: Học vụ | E41: NGAY | F41: session_status = scheduled (lịch bù mới)
A43: PHASE 6: ĐIỂM DANH
A44: Tình huống | B44: Điều kiện | C44: Hành động | D44: Người làm | E44: SLA | F44: Kết quả / Trạng thái mới
A45: class_start_actual đã ghi nhận (GV bấm "Bắt đầu" buổi) | B45: GV bấm "Bắt đầu" (class_start_actual ghi nhận) | C45: Mở app điểm danh | D45: GV | E45: - | F45: -
...

Sheet HD3. Sổ trigger & tự động
A1: HD3 - SỔ TRIGGER & TỰ ĐỘNG HÓA (mọi thứ hệ thống tự làm, tra cứu tại đây)
A2: 5 phần: (1) Nhắc việc & gợi ý chuyển trạng thái - điều kiện nào ra câu nào; (2) Dấu giờ tự động - đổi trạng thái là hệ thống tự điền giờ; (3) Quy tắc màu; (4) Cột tự tính - cột nào không nhập tay; (5) Bảng báo cáo tự lọc. Cột "Mở ô" bấm để nhảy thẳng tới công thức thật đang chạy.
A4: Loại | B4: Tình huống | C4: KHI NÀO / CÁCH TÍNH | D4: Mã | E4: Nội dung hiển thị | F4: Người phụ trách | G4: Chỉnh NGƯỠNG tại | H4: Chỉnh CÂU tại | I4: Mở ô (xem thử)
A5: PHẦN 1 - NHẮC VIỆC (next_action) & GỢI Ý CHUYỂN TRẠNG THÁI (auto_trigger_hint)
A6: DL02. Khách tiềm năng
A7: next_action | B7: Lead giao quá hạn chưa gọi | C7: lead_status chưa đóng, đã có assigned_to (NV phụ trách) nhưng first_call_time (giờ liên hệ đầu) còn trống, và kể từ lead_created_time (giờ tạo lead) đã quá slaLeadReassign_hours | D7: NA046 | E7: {=IFERROR(INDEX('CH4. Thông điệp nhắc việc'!$G:$G,MATCH($D7,'CH4. Thông điệp nhắc việc'!$A:$A,0)),"")} -> Lead đã giao cho NV nhưng quá 4 giờ (cấu hình slaLeadReassign_hours) chưa gọi. Việc cần làm: gọi gấp hoặc giao lại cho NV khác. | F7: {=IFERROR(INDEX('CH4. Thông điệp nhắc việc'!$E:$E,MATCH($D7,'CH4. Thông điệp nhắc việc'!$A:$A,0)),"-")} -> NV Tư vấn | G7: =HYPERLINK("#'CH2. Tham số & Quy tắc'!B"&MATCH("slaLeadReassign_hours",'CH2. Tham số & Quy tắc'!$A:$A,0),"CH2: slaLeadReassign_hours") -> CH2: slaLeadReassign_hours | H7: =HYPERLINK("#'CH4. Thông điệp nhắc việc'!C"&MATCH("NA046",'CH4. Thông điệp nhắc việc'!$A:$A,0),"CH4: NA046") -> CH4: NA046 | I7: =HYPERLINK("#'DL02. Khách tiềm năng'!T4","Mở ô") -> Mở ô
A8: next_action | B8: Gọi đủ số lần, không phản hồi | C8: contact_count (số lần liên hệ) ≥ thresholdContacted_attempts và lead_status là no_response/considering | D8: NA047 | E8: {=IFERROR(INDEX('CH4. Thông điệp nhắc việc'!$G:$G,MATCH($D8,'CH4. Thông điệp nhắc việc'!$A:$A,0)),"")} -> Đã liên hệ đủ 5 lần (cấu hình thresholdContacted_attempts) mà khách không phản hồi. Việc cần làm: cân nhắc chuyển lead sang trạng thái không liên lạc được. | F8: {=IFERROR(INDEX('CH4. Thông điệp nhắc việc'!$E:$E,MATCH($D8,'CH4. Thông điệp nhắc việc'!$A:$A,0)),"-")} -> NV Tư vấn | G8: =HYPERLINK("#'CH2. Tham số & Quy tắc'!B"&MATCH("thresholdContacted_attempts",'CH2. Tham số & Quy tắc'!$A:$A,0),"CH2: thresholdContacted_attempts") -> CH2: thresholdContacted_attempts | H8: =HYPERLINK("#'CH4. Thông điệp nhắc việc'!C"&MATCH("NA047",'CH4. Thông điệp nhắc việc'!$A:$A,0),"CH4: NA047") -> CH4: NA047 | I8: =HYPERLINK("#'DL02. Khách tiềm năng'!T4","Mở ô") -> Mở ô
A9: next_action | B9: Đã liên hệ, quá ngày chưa chốt | C9: lead_status = contacted và kể từ last_contact_time (liên hệ gần nhất) đã quá thresholdContacted_days | D9: NA048 | E9: {=IFERROR(INDEX('CH4. Thông điệp nhắc việc'!$G:$G,MATCH($D9,'CH4. Thông điệp nhắc việc'!$A:$A,0)),"")} -> Đã liên hệ nhưng quá 7 ngày (cấu hình thresholdContacted_days) chưa chốt. Việc cần làm: đẩy mạnh tư vấn để chốt. | F9: {=IFERROR(INDEX('CH4. Thông điệp nhắc việc'!$E:$E,MATCH($D9,'CH4. Thông điệp nhắc việc'!$A:$A,0)),"-")} -> NV Tư vấn | G9: =HYPERLINK("#'CH2. Tham số & Quy tắc'!B"&MATCH("thresholdContacted_days",'CH2. Tham số & Quy tắc'!$A:$A,0),"CH2: thresholdContacted_days") -> CH2: thresholdContacted_days | H9: =HYPERLINK("#'CH4. Thông điệp nhắc việc'!C"&MATCH("NA048",'CH4. Thông điệp nhắc việc'!$A:$A,0),"CH4: NA048") -> CH4: NA048 | I9: =HYPERLINK("#'DL02. Khách tiềm năng'!T4","Mở ô") -> Mở ô
A10: next_action | B10: Lead mới quá hạn phản hồi | C10: lead_status = new và kể từ lead_created_time đã quá slaLRT_minutes phút | D10: NA049 | E10: {=IFERROR(INDEX('CH4. Thông điệp nhắc việc'!$G:$G,MATCH($D10,'CH4. Thông điệp nhắc việc'!$A:$A,0)),"")} -> Lead mới đã quá 15 phút (cấu hình slaLRT_minutes) chưa được liên hệ. Việc cần làm: GỌI NGAY để không mất lead. | F10: {=IFERROR(INDEX('CH4. Thông điệp nhắc việc'!$E:$E,MATCH($D10,'CH4. Thông điệp nhắc việc'!$A:$A,0)),"-")} -> NV Tư vấn | G10: =HYPERLINK("#'CH2. Tham số & Quy tắc'!B"&MATCH("slaLRT_minutes",'CH2. Tham số & Quy tắc'!$A:$A,0),"CH2: slaLRT_minutes") -> CH2: slaLRT_minutes | H10: =HYPERLINK("#'CH4. Thông điệp nhắc việc'!C"&MATCH("NA049",'CH4. Thông điệp nhắc việc'!$A:$A,0),"CH4: NA049") -> CH4: NA049 | I10: =HYPERLINK("#'DL02. Khách tiềm năng'!T4","Mở ô") -> Mở ô
A11: next_action | B11: Lead mới còn trong hạn | C11: lead_status = new và còn trong hạn slaLRT_minutes phút kể từ lead_created_time | D11: NA050 | E11: {=IFERROR(INDEX('CH4. Thông điệp nhắc việc'!$G:$G,MATCH($D11,'CH4. Thông điệp nhắc việc'!$A:$A,0)),"")} -> Lead mới, còn trong hạn phản hồi 15 phút (cấu hình slaLRT_minutes). Việc cần làm: liên hệ khách càng sớm càng tốt. | F11: {=IFERROR(INDEX('CH4. Thông điệp nhắc việc'!$E:$E,MATCH($D11,'CH4. Thông điệp nhắc việc'!$A:$A,0)),"-")} -> NV Tư vấn | G11: =HYPERLINK("#'CH2. Tham số & Quy tắc'!B"&MATCH("slaLRT_minutes",'CH2. Tham số & Quy tắc'!$A:$A,0),"CH2: slaLRT_minutes") -> CH2: slaLRT_minutes | H11: =HYPERLINK("#'CH4. Thông điệp nhắc việc'!C"&MATCH("NA050",'CH4. Thông điệp nhắc việc'!$A:$A,0),"CH4: NA050") -> CH4: NA050 | I11: =HYPERLINK("#'DL02. Khách tiềm năng'!T4","Mở ô") -> Mở ô
A12: next_action | B12: Tới/quá hẹn theo dõi | C12: lead_status = contacted/considering/no_response và next_followup_time (lịch liên hệ tiếp) ≤ hôm nay | D12: NA051 | E12: {=IFERROR(INDEX('CH4. Thông điệp nhắc việc'!$G:$G,MATCH($D12,'CH4. Thông điệp nhắc việc'!$A:$A,0)),"")} -> Đã tới hoặc quá hẹn theo dõi lead. Việc cần làm: liên hệ lại ngay. | F12: {=IFERROR(INDEX('CH4. Thông điệp nhắc việc'!$E:$E,MATCH($D12,'CH4. Thông điệp nhắc việc'!$A:$A,0)),"-")} -> NV Tư vấn | G12: - | H12: =HYPERLINK("#'CH4. Thông điệp nhắc việc'!C"&MATCH("NA051",'CH4. Thông điệp nhắc việc'!$A:$A,0),"CH4: NA051") -> CH4: NA051 | I12: =HYPERLINK("#'DL02. Khách tiềm năng'!T4","Mở ô") -> Mở ô
A13: next_action | B13: Sắp tới hẹn theo dõi | C13: next_followup_time (lịch liên hệ tiếp) ≤ hôm nay + 1 (trong 24 giờ) | D13: NA052 | E13: {=IFERROR(INDEX('CH4. Thông điệp nhắc việc'!$G:$G,MATCH($D13,'CH4. Thông điệp nhắc việc'!$A:$A,0)),"")} -> Sắp tới hẹn theo dõi lead (trong vòng 24 giờ). Việc cần làm: chuẩn bị liên hệ khách. | F13: {=IFERROR(INDEX('CH4. Thông điệp nhắc việc'!$E:$E,MATCH($D13,'CH4. Thông điệp nhắc việc'!$A:$A,0)),"-")} -> NV Tư vấn | G13: - | H13: =HYPERLINK("#'CH4. Thông điệp nhắc việc'!C"&MATCH("NA052",'CH4. Thông điệp nhắc việc'!$A:$A,0),"CH4: NA052") -> CH4: NA052 | I13: =HYPERLINK("#'DL02. Khách tiềm năng'!T4","Mở ô") -> Mở ô
A14: next_action | B14: Lead đã đóng | C14: lead_status = rejected (từ chối) hoặc unreachable (không liên lạc được) | D14: NA053 | E14: {=IFERROR(INDEX('CH4. Thông điệp nhắc việc'!$G:$G,MATCH($D14,'CH4. Thông điệp nhắc việc'!$A:$A,0)),"")} -> Lead đã đóng (từ chối hoặc không liên lạc được). Không cần làm gì thêm. | F14: {=IFERROR(INDEX('CH4. Thông điệp nhắc việc'!$E:$E,MATCH($D14,'CH4. Thông điệp nhắc việc'!$A:$A,0)),"-")} -> - | G14: - | H14: =HYPERLINK("#'CH4. Thông điệp nhắc việc'!C"&MATCH("NA053",'CH4. Thông điệp nhắc việc'!$A:$A,0),"CH4: NA053") -> CH4: NA053 | I14: =HYPERLINK("#'DL02. Khách tiềm năng'!T4","Mở ô") -> Mở ô
A15: DL03. Đặt lịch test
A16: next_action | B16: Có bài test, quá hạn chấm | C16: test_attendance_status (kết quả điểm danh) = on_time/late + test_status (trạng thái chấm bài) = pending, và kể từ test_attendance_time (giờ vào test thực tế) đã quá slaGLA_hours | D16: NA054 | E16: {=IFERROR(INDEX('CH4. Thông điệp nhắc việc'!$G:$G,MATCH($D16,'CH4. Thông điệp nhắc việc'!$A:$A,0)),"")} -> Khách đã làm test nhưng quá 24 giờ (cấu hình slaGLA_hours) chưa chấm bài. Việc cần làm: chấm bài test ngay. | F16: {=IFERROR(INDEX('CH4. Thông điệp nhắc việc'!$E:$E,MATCH($D16,'CH4. Thông điệp nhắc việc'!$A:$A,0)),"-")} -> Người chấm test | G16: =HYPERLINK("#'CH2. Tham số & Quy tắc'!B"&MATCH("slaGLA_hours",'CH2. Tham số & Quy tắc'!$A:$A,0),"CH2: slaGLA_hours") -> CH2: slaGLA_hours | H16: =HYPERLINK("#'CH4. Thông điệp nhắc việc'!C"&MATCH("NA054",'CH4. Thông điệp nhắc việc'!$A:$A,0),"CH4: NA054") -> CH4: NA054 | I16: =HYPERLINK("#'DL03. Đặt lịch test'!U4","Mở ô") -> Mở ô
A17: next_action | B17: Có bài test, còn trong hạn chấm | C17: test_attendance_status = on_time/late + test_status = pending, còn trong hạn slaGLA_hours kể từ test_attendance_time | D17: NA055 | E17: {=IFERROR(INDEX('CH4. Thông điệp nhắc việc'!$G:$G,MATCH($D17,'CH4. Thông điệp nhắc việc'!$A:$A,0)),"")} -> Bài test chờ chấm, còn trong hạn 24 giờ (cấu hình slaGLA_hours). Việc cần làm: chấm bài sớm để kịp tư vấn. | F17: {=IFERROR(INDEX('CH4. Thông điệp nhắc việc'!$E:$E,MATCH($D17,'CH4. Thông điệp nhắc việc'!$A:$A,0)),"-")} -> Người chấm test | G17: =HYPERLINK("#'CH2. Tham số & Quy tắc'!B"&MATCH("slaGLA_hours",'CH2. Tham số & Quy tắc'!$A:$A,0),"CH2: slaGLA_hours") -> CH2: slaGLA_hours | H17: =HYPERLINK("#'CH4. Thông điệp nhắc việc'!C"&MATCH("NA055",'CH4. Thông điệp nhắc việc'!$A:$A,0),"CH4: NA055") -> CH4: NA055 | I17: =HYPERLINK("#'DL03. Đặt lịch test'!U4","Mở ô") -> Mở ô
A18: next_action | B18: Đã chấm, chưa chuyển trạng thái | C18: test_status = graded (đã chấm xong) và post_test_status (trạng thái sau test) còn trống | D18: NA056 | E18: {=IFERROR(INDEX('CH4. Thông điệp nhắc việc'!$G:$G,MATCH($D18,'CH4. Thông điệp nhắc việc'!$A:$A,0)),"")} -> Đã chấm xong bài test. Việc cần làm: chuyển trạng thái sau test sang chờ tư vấn (awaiting). | F18: {=IFERROR(INDEX('CH4. Thông điệp nhắc việc'!$E:$E,MATCH($D18,'CH4. Thông điệp nhắc việc'!$A:$A,0)),"-")} -> NV Tư vấn | G18: - | H18: =HYPERLINK("#'CH4. Thông điệp nhắc việc'!C"&MATCH("NA056",'CH4. Thông điệp nhắc việc'!$A:$A,0),"CH4: NA056") -> CH4: NA056 | I18: =HYPERLINK("#'DL03. Đặt lịch test'!U4","Mở ô") -> Mở ô
A19: next_action | B19: Quá hạn tư vấn sau test | C19: post_test_status = awaiting (chờ tư vấn) và kể từ result_time (thời gian trả kết quả) đã quá slaCVT_hours | D19: NA001 | E19: {=IFERROR(INDEX('CH4. Thông điệp nhắc việc'!$G:$G,MATCH($D19,'CH4. Thông điệp nhắc việc'!$A:$A,0)),"")} -> Khách đã có kết quả test nhưng quá 24 giờ (cấu hình slaCVT_hours) chưa được tư vấn. Việc cần làm: tư vấn ngay để chốt khi khách còn quan tâm. | F19: {=IFERROR(INDEX('CH4. Thông điệp nhắc việc'!$E:$E,MATCH($D19,'CH4. Thông điệp nhắc việc'!$A:$A,0)),"-")} -> NV Tư vấn | G19: =HYPERLINK("#'CH2. Tham số & Quy tắc'!B"&MATCH("slaCVT_hours",'CH2. Tham số & Quy tắc'!$A:$A,0),"CH2: slaCVT_hours") -> CH2: slaCVT_hours | H19: =HYPERLINK("#'CH4. Thông điệp nhắc việc'!C"&MATCH("NA001",'CH4. Thông điệp nhắc việc'!$A:$A,0),"CH4: NA001") -> CH4: NA001 | I19: =HYPERLINK("#'DL03. Đặt lịch test'!U4","Mở ô") -> Mở ô
A20: next_action | B20: Đã tư vấn xong | C20: post_test_status = consulted (đã tư vấn) | D20: NA002 | E20: {=IFERROR(INDEX('CH4. Thông điệp nhắc việc'!$G:$G,MATCH($D20,'CH4. Thông điệp nhắc việc'!$A:$A,0)),"")} -> Đã tư vấn xong cho khách. Không cần làm gì thêm ở bước này. | F20: {=IFERROR(INDEX('CH4. Thông điệp nhắc việc'!$E:$E,MATCH($D20,'CH4. Thông điệp nhắc việc'!$A:$A,0)),"-")} -> NV Tư vấn | G20: - | H20: =HYPERLINK("#'CH4. Thông điệp nhắc việc'!C"&MATCH("NA002",'CH4. Thông điệp nhắc việc'!$A:$A,0),"CH4: NA002") -> CH4: NA002 | I20: =HYPERLINK("#'DL03. Đặt lịch test'!U4","Mở ô") -> Mở ô
A21: auto_trigger_hint | B21: Chấm xong, cần chuyển trạng thái | C21: test_status = graded (đã chấm xong) và post_test_status (trạng thái sau test) còn trống | D21: NA085 | E21: {=IFERROR(INDEX('CH4. Thông điệp nhắc việc'!$G:$G,MATCH($D21,'CH4. Thông điệp nhắc việc'!$A:$A,0)),"")} -> Cập nhật post_test_status = awaiting_consultation (chờ tư vấn) | F21: {=IFERROR(INDEX('CH4. Thông điệp nhắc việc'!$E:$E,MATCH($D21,'CH4. Thông điệp nhắc việc'!$A:$A,0)),"-")} -> Học vụ / hệ thống | G21: - | H21: =HYPERLINK("#'CH4. Thông điệp nhắc việc'!C"&MATCH("NA085",'CH4. Thông điệp nhắc việc'!$A:$A,0),"CH4: NA085") -> CH4: NA085 | I21: =HYPERLINK("#'DL03. Đặt lịch test'!T4","Mở ô") -> Mở ô
A22: auto_trigger_hint | B22: Chờ tư vấn, cần tạo bản ghi TV | C22: test_status = graded và post_test_status = awaiting (chờ tư vấn) | D22: NA086 | E22: {=IFERROR(INDEX('CH4. Thông điệp nhắc việc'!$G:$G,MATCH($D22,'CH4. Thông điệp nhắc việc'!$A:$A,0)),"")} -> Tạo Tư vấn mới (CS-...) cho lead này ở sheet DL04 | F22: {=IFERROR(INDEX('CH4. Thông điệp nhắc việc'!$E:$E,MATCH($D22,'CH4. Thông điệp nhắc việc'!$A:$A,0)),"-")} -> NV Tư vấn | G22: - | H22: =HYPERLINK("#'CH4. Thông điệp nhắc việc'!C"&MATCH("NA086",'CH4. Thông điệp nhắc việc'!$A:$A,0),"CH4: NA086") -> CH4: NA086 | I22: =HYPERLINK("#'DL03. Đặt lịch test'!T4","Mở ô") -> Mở ô
A23: DL04. Tư vấn
A24: next_action | B24: Quan tâm, quá hạn chưa chốt | C24: conversion_status (kết quả tư vấn) = interested và kể từ conversion_time (thời gian cập nhật kết quả) đã quá slaFollowup_grace_days | D24: NA003 | E24: {=IFERROR(INDEX('CH4. Thông điệp nhắc việc'!$G:$G,MATCH($D24,'CH4. Thông điệp nhắc việc'!$A:$A,0)),"")} -> Khách quan tâm nhưng đã quá 3 ngày (cấu hình slaFollowup_grace_days) chưa chốt. Việc cần làm: liên hệ chốt ngay khi khách còn quan tâm. | F24: {=IFERROR(INDEX('CH4. Thông điệp nhắc việc'!$E:$E,MATCH($D24,'CH4. Thông điệp nhắc việc'!$A:$A,0)),"-")} -> NV Tư vấn | G24: =HYPERLINK("#'CH2. Tham số & Quy tắc'!B"&MATCH("slaFollowup_grace_days",'CH2. Tham số & Quy tắc'!$A:$A,0),"CH2: slaFollowup_grace_days") -> CH2: slaFollowup_grace_days | H24: =HYPERLINK("#'CH4. Thông điệp nhắc việc'!C"&MATCH("NA003",'CH4. Thông điệp nhắc việc'!$A:$A,0),"CH4: NA003") -> CH4: NA003 | I24: =HYPERLINK("#'DL04. Tư vấn'!N4","Mở ô") -> Mở ô
A25: next_action | B25: Đồng ý + đặt cọc | C25: conversion_status = confirmed_with_deposit | D25: NA057 | E25: {=IFERROR(INDEX('CH4. Thông điệp nhắc việc'!$G:$G,MATCH($D25,'CH4. Thông điệp nhắc việc'!$A:$A,0)),"")} -> Khách đã đồng ý và đặt cọc. Việc cần làm: tạo đăng ký và thu cọc (chuyển sang sheet DL06 Đăng ký). | F25: {=IFERROR(INDEX('CH4. Thông điệp nhắc việc'!$E:$E,MATCH($D25,'CH4. Thông điệp nhắc việc'!$A:$A,0)),"-")} -> NV Tư vấn | G25: - | H25: =HYPERLINK("#'CH4. Thông điệp nhắc việc'!C"&MATCH("NA057",'CH4. Thông điệp nhắc việc'!$A:$A,0),"CH4: NA057") -> CH4: NA057 | I25: =HYPERLINK("#'DL04. Tư vấn'!N4","Mở ô") -> Mở ô
A26: next_action | B26: Khách bỏ | C26: conversion_status = dropped | D26: NA058 | E26: {=IFERROR(INDEX('CH4. Thông điệp nhắc việc'!$G:$G,MATCH($D26,'CH4. Thông điệp nhắc việc'!$A:$A,0)),"")} -> Khách đã bỏ, không tiếp tục. Không cần làm gì thêm. | F26: {=IFERROR(INDEX('CH4. Thông điệp nhắc việc'!$E:$E,MATCH($D26,'CH4. Thông điệp nhắc việc'!$A:$A,0)),"-")} -> - | G26: - | H26: =HYPERLINK("#'CH4. Thông điệp nhắc việc'!C"&MATCH("NA058",'CH4. Thông điệp nhắc việc'!$A:$A,0),"CH4: NA058") -> CH4: NA058 | I26: =HYPERLINK("#'DL04. Tư vấn'!N4","Mở ô") -> Mở ô
A27: next_action | B27: Chưa quyết định | C27: conversion_status = undecided | D27: NA004 | E27: {=IFERROR(INDEX('CH4. Thông điệp nhắc việc'!$G:$G,MATCH($D27,'CH4. Thông điệp nhắc việc'!$A:$A,0)),"")} -> Khách chưa quyết định, vẫn trong thời gian theo dõi cho phép. Việc cần làm: tiếp tục theo dõi và chăm sóc. | F27: {=IFERROR(INDEX('CH4. Thông điệp nhắc việc'!$E:$E,MATCH($D27,'CH4. Thông điệp nhắc việc'!$A:$A,0)),"-")} -> NV Tư vấn | G27: - | H27: =HYPERLINK("#'CH4. Thông điệp nhắc việc'!C"&MATCH("NA004",'CH4. Thông điệp nhắc việc'!$A:$A,0),"CH4: NA004") -> CH4: NA004 | I27: =HYPERLINK("#'DL04. Tư vấn'!N4","Mở ô") -> Mở ô
A28: DL06. Đăng ký
A29: next_action | B29: Đăng ký đã hủy | C29: enrollment_status (trạng thái đăng ký) = cancelled | D29: NA059 | E29: {=IFERROR(INDEX('CH4. Thông điệp nhắc việc'!$G:$G,MATCH($D29,'CH4. Thông điệp nhắc việc'!$A:$A,0)),"")} -> Đăng ký đã hủy. Chính sách hoàn tiền (cấu hình): hoàn 100% nếu hủy trong 7 ngày, hoàn một phần nếu trong 14 ngày, hoàn mức thấp nếu trong 30 ngày, quá thì không hoàn. Việc cần làm: kiểm tra ngày hủy và xử lý hoàn tiền. | F29: {=IFERROR(INDEX('CH4. Thông điệp nhắc việc'!$E:$E,MATCH($D29,'CH4. Thông điệp nhắc việc'!$A:$A,0)),"-")} -> Kế toán / Học vụ | G29: =HYPERLINK("#'CH2. Tham số & Quy tắc'!B"&MATCH("refundFull_days",'CH2. Tham số & Quy tắc'!$A:$A,0),"CH2: refundFull_days +2") -> CH2: refundFull_days +2 | H29: =HYPERLINK("#'CH4. Thông điệp nhắc việc'!C"&MATCH("NA059",'CH4. Thông điệp nhắc việc'!$A:$A,0),"CH4: NA059") -> CH4: NA059 | I29: =HYPERLINK("#'DL06. Đăng ký'!T4","Mở ô") -> Mở ô
A30: next_action | B30: Chờ quá hạn (nên hủy) | C30: enrollment_status = pending và kể từ enrollment_time (thời gian xác nhận) đã quá slaENR_cancel_hours | D30: NA060 | E30: {=IFERROR(INDEX('CH4. Thông điệp nhắc việc'!$G:$G,MATCH($D30,'CH4. Thông điệp nhắc việc'!$A:$A,0)),"")} -> Đăng ký để ở trạng thái chờ quá 72 giờ (cấu hình slaENR_cancel_hours). Việc cần làm: cân nhắc hủy đăng ký ngay để dọn dữ liệu ảo. | F30: {=IFERROR(INDEX('CH4. Thông điệp nhắc việc'!$E:$E,MATCH($D30,'CH4. Thông điệp nhắc việc'!$A:$A,0)),"-")} -> NV Tư vấn / Học vụ | G30: =HYPERLINK("#'CH2. Tham số & Quy tắc'!B"&MATCH("slaENR_cancel_hours",'CH2. Tham số & Quy tắc'!$A:$A,0),"CH2: slaENR_cancel_hours") -> CH2: slaENR_cancel_hours | H30: =HYPERLINK("#'CH4. Thông điệp nhắc việc'!C"&MATCH("NA060",'CH4. Thông điệp nhắc việc'!$A:$A,0),"CH4: NA060") -> CH4: NA060 | I30: =HYPERLINK("#'DL06. Đăng ký'!T4","Mở ô") -> Mở ô
A31: next_action | B31: Giảm giá vượt mức | C31: discount_amount (tiền chiết khấu) > thresholdDiscount_approval và discount_approved_by (người duyệt) còn trống | D31: NA061 | E31: {=IFERROR(INDEX('CH4. Thông điệp nhắc việc'!$G:$G,MATCH($D31,'CH4. Thông điệp nhắc việc'!$A:$A,0)),"")} -> Khoản giảm giá vượt mức cho phép 1,000,000đ (cấu hình thresholdDiscount_approval). Việc cần làm: trình cấp trên duyệt trước khi áp dụng. | F31: {=IFERROR(INDEX('CH4. Thông điệp nhắc việc'!$E:$E,MATCH($D31,'CH4. Thông điệp nhắc việc'!$A:$A,0)),"-")} -> Quản lý | G31: =HYPERLINK("#'CH2. Tham số & Quy tắc'!B"&MATCH("thresholdDiscount_approval",'CH2. Tham số & Quy tắc'!$A:$A,0),"CH2: thresholdDiscount_approval") -> CH2: thresholdDiscount_approval | H31: =HYPERLINK("#'CH4. Thông điệp nhắc việc'!C"&MATCH("NA061",'CH4. Thông điệp nhắc việc'!$A:$A,0),"CH4: NA061") -> CH4: NA061 | I31: =HYPERLINK("#'DL06. Đăng ký'!T4","Mở ô") -> Mở ô
A32: next_action | B32: Chờ quá hạn xác nhận | C32: enrollment_status = pending và kể từ enrollment_time đã quá slaENR_pending_hours | D32: NA005 | E32: {=IFERROR(INDEX('CH4. Thông điệp nhắc việc'!$G:$G,MATCH($D32,'CH4. Thông điệp nhắc việc'!$A:$A,0)),"")} -> Đăng ký ở trạng thái chờ đã quá 24 giờ (cấu hình slaENR_pending_hours). Việc cần làm: xác nhận hoặc hủy đăng ký ngay. | F32: {=IFERROR(INDEX('CH4. Thông điệp nhắc việc'!$E:$E,MATCH($D32,'CH4. Thông điệp nhắc việc'!$A:$A,0)),"-")} -> NV Tư vấn / Học vụ | G32: =HYPERLINK("#'CH2. Tham số & Quy tắc'!B"&MATCH("slaENR_pending_hours",'CH2. Tham số & Quy tắc'!$A:$A,0),"CH2: slaENR_pending_hours") -> CH2: slaENR_pending_hours | H32: =HYPERLINK("#'CH4. Thông điệp nhắc việc'!C"&MATCH("NA005",'CH4. Thông điệp nhắc việc'!$A:$A,0),"CH4: NA005") -> CH4: NA005 | I32: =HYPERLINK("#'DL06. Đăng ký'!T4","Mở ô") -> Mở ô
A33: next_action | B33: Xác nhận nhưng chưa thu tiền | C33: enrollment_status = confirmed và payment_status (trạng thái thanh toán) = unpaid | D33: NA006 | E33: {=IFERROR(INDEX('CH4. Thông điệp nhắc việc'!$G:$G,MATCH($D33,'CH4. Thông điệp nhắc việc'!$A:$A,0)),"")} -> Đăng ký đã xác nhận nhưng chưa thu được tiền. Việc cần làm: thu học phí ngay. | F33: {=IFERROR(INDEX('CH4. Thông điệp nhắc việc'!$E:$E,MATCH($D33,'CH4. Thông điệp nhắc việc'!$A:$A,0)),"-")} -> NV Tư vấn | G33: - | H33: =HYPERLINK("#'CH4. Thông điệp nhắc việc'!C"&MATCH("NA006",'CH4. Thông điệp nhắc việc'!$A:$A,0),"CH4: NA006") -> CH4: NA006 | I33: =HYPERLINK("#'DL06. Đăng ký'!T4","Mở ô") -> Mở ô
A34: next_action | B34: Còn nợ học phí và quá hạn | C34: payment_status = partial + remaining_amount (còn lại) > 0, và kể từ enrollment_time đã quá slaPayment_grace_days | D34: NA007 | E34: {=IFERROR(INDEX('CH4. Thông điệp nhắc việc'!$G:$G,MATCH($D34,'CH4. Thông điệp nhắc việc'!$A:$A,0)),"")} -> Còn khoản học phí chưa đóng và đã quá hạn 14 ngày (cấu hình slaPayment_grace_days). Việc cần làm: nhắc HV đóng phần còn lại ngay. | F34: {=IFERROR(INDEX('CH4. Thông điệp nhắc việc'!$E:$E,MATCH($D34,'CH4. Thông điệp nhắc việc'!$A:$A,0)),"-")} -> NV Tư vấn | G34: =HYPERLINK("#'CH2. Tham số & Quy tắc'!B"&MATCH("slaPayment_grace_days",'CH2. Tham số & Quy tắc'!$A:$A,0),"CH2: slaPayment_grace_days") -> CH2: slaPayment_grace_days | H34: =HYPERLINK("#'CH4. Thông điệp nhắc việc'!C"&MATCH("NA007",'CH4. Thông điệp nhắc việc'!$A:$A,0),"CH4: NA007") -> CH4: NA007 | I34: =HYPERLINK("#'DL06. Đăng ký'!T4","Mở ô") -> Mở ô
A35: next_action | B35: Xác nhận + đóng đủ | C35: enrollment_status = confirmed và payment_status = paid | D35: NA009 | E35: {=IFERROR(INDEX('CH4. Thông điệp nhắc việc'!$G:$G,MATCH($D35,'CH4. Thông điệp nhắc việc'!$A:$A,0)),"")} -> Đăng ký đã xác nhận và HV đã đóng đủ tiền. Không cần làm gì thêm. | F35: {=IFERROR(INDEX('CH4. Thông điệp nhắc việc'!$E:$E,MATCH($D35,'CH4. Thông điệp nhắc việc'!$A:$A,0)),"-")} -> - | G35: - | H35: =HYPERLINK("#'CH4. Thông điệp nhắc việc'!C"&MATCH("NA009",'CH4. Thông điệp nhắc việc'!$A:$A,0),"CH4: NA009") -> CH4: NA009 | I35: =HYPERLINK("#'DL06. Đăng ký'!T4","Mở ô") -> Mở ô
A36: auto_trigger_hint | B36: Đủ cọc, còn ở trạng thái chờ | C36: paid_amount (đã thanh toán) ≥ thresholdDeposit_minimum và enrollment_status = pending | D36: NA087 | E36: {=IFERROR(INDEX('CH4. Thông điệp nhắc việc'!$G:$G,MATCH($D36,'CH4. Thông điệp nhắc việc'!$A:$A,0)),"")} -> Đã đủ cọc tối thiểu 5,000,000đ - chuyển enrollment_status = confirmed và tạo Onboarding (DL08) | F36: {=IFERROR(INDEX('CH4. Thông điệp nhắc việc'!$E:$E,MATCH($D36,'CH4. Thông điệp nhắc việc'!$A:$A,0)),"-")} -> Kế toán / Học vụ | G36: =HYPERLINK("#'CH2. Tham số & Quy tắc'!B"&MATCH("thresholdDeposit_minimum",'CH2. Tham số & Quy tắc'!$A:$A,0),"CH2: thresholdDeposit_minimum") -> CH2: thresholdDeposit_minimum | H36: =HYPERLINK("#'CH4. Thông điệp nhắc việc'!C"&MATCH("NA087",'CH4. Thông điệp nhắc việc'!$A:$A,0),"CH4: NA087") -> CH4: NA087 | I36: =HYPERLINK("#'DL06. Đăng ký'!S4","Mở ô") -> Mở ô
A37: auto_trigger_hint | B37: Đã thanh toán đủ | C37: payment_status = paid (không phải partial/unpaid) | D37: NA088 | E37: {=IFERROR(INDEX('CH4. Thông điệp nhắc việc'!$G:$G,MATCH($D37,'CH4. Thông điệp nhắc việc'!$A:$A,0)),"")} -> Đã thanh toán đủ - chuyển sang Onboarding (DL08) nếu chưa | F37: {=IFERROR(INDEX('CH4. Thông điệp nhắc việc'!$E:$E,MATCH($D37,'CH4. Thông điệp nhắc việc'!$A:$A,0)),"-")} -> Kế toán / Học vụ | G37: - | H37: =HYPERLINK("#'CH4. Thông điệp nhắc việc'!C"&MATCH("NA088",'CH4. Thông điệp nhắc việc'!$A:$A,0),"CH4: NA088") -> CH4: NA088 | I37: =HYPERLINK("#'DL06. Đăng ký'!S4","Mở ô") -> Mở ô
A38: DL08. Xếp lớp & Nhập học
A39: next_action | B39: Quá hạn gửi thông tin Zalo | C39: placement_status (trạng thái xếp lớp) = assigned + class_confirmation_status (xác nhận lớp của HV) = pending, và kể từ assigned_at (thời gian xếp lớp) đã quá slaClassInfoZalo_hours | D39: NA062 | E39: {=IFERROR(INDEX('CH4. Thông điệp nhắc việc'!$G:$G,MATCH($D39,'CH4. Thông điệp nhắc việc'!$A:$A,0)),"")} -> Đã xếp lớp nhưng quá 24 giờ (cấu hình slaClassInfoZalo_hours) chưa gửi thông tin lớp. Việc cần làm: gửi thông tin lớp qua Zalo cho HV ngay. | F39: {=IFERROR(INDEX('CH4. Thông điệp nhắc việc'!$E:$E,MATCH($D39,'CH4. Thông điệp nhắc việc'!$A:$A,0)),"-")} -> Học vụ | G39: =HYPERLINK("#'CH2. Tham số & Quy tắc'!B"&MATCH("slaClassInfoZalo_hours",'CH2. Tham số & Quy tắc'!$A:$A,0),"CH2: slaClassInfoZalo_hours") -> CH2: slaClassInfoZalo_hours | H39: =HYPERLINK("#'CH4. Thông điệp nhắc việc'!C"&MATCH("NA062",'CH4. Thông điệp nhắc việc'!$A:$A,0),"CH4: NA062") -> CH4: NA062 | I39: =HYPERLINK("#'DL08. Xếp lớp & Nhập học'!Q4","Mở ô") -> Mở ô
A40: next_action | B40: Quá hạn xếp lớp | C40: placement_status = not_assigned và kể từ assigned_at đã quá slaPLR48_hours | D40: NA063 | E40: {=IFERROR(INDEX('CH4. Thông điệp nhắc việc'!$G:$G,MATCH($D40,'CH4. Thông điệp nhắc việc'!$A:$A,0)),"")} -> Đăng ký đã xác nhận nhưng quá 48 giờ (cấu hình slaPLR48_hours) chưa xếp lớp. Việc cần làm: xếp lớp ngay. | F40: {=IFERROR(INDEX('CH4. Thông điệp nhắc việc'!$E:$E,MATCH($D40,'CH4. Thông điệp nhắc việc'!$A:$A,0)),"-")} -> Học vụ | G40: =HYPERLINK("#'CH2. Tham số & Quy tắc'!B"&MATCH("slaPLR48_hours",'CH2. Tham số & Quy tắc'!$A:$A,0),"CH2: slaPLR48_hours") -> CH2: slaPLR48_hours | H40: =HYPERLINK("#'CH4. Thông điệp nhắc việc'!C"&MATCH("NA063",'CH4. Thông điệp nhắc việc'!$A:$A,0),"CH4: NA063") -> CH4: NA063 | I40: =HYPERLINK("#'DL08. Xếp lớp & Nhập học'!Q4","Mở ô") -> Mở ô
A41: next_action | B41: Quá hạn nhập học (đã xếp) | C41: placement_status = assigned và kể từ assigned_at đã quá slaOBT_hours | D41: NA010 | E41: {=IFERROR(INDEX('CH4. Thông điệp nhắc việc'!$G:$G,MATCH($D41,'CH4. Thông điệp nhắc việc'!$A:$A,0)),"")} -> Đã xếp lớp nhưng quá 72 giờ (cấu hình slaOBT_hours) chưa hoàn tất nhập học. Việc cần làm: kiểm tra và đẩy nhanh nhập học ngay. | F41: {=IFERROR(INDEX('CH4. Thông điệp nhắc việc'!$E:$E,MATCH($D41,'CH4. Thông điệp nhắc việc'!$A:$A,0)),"-")} -> Học vụ | G41: =HYPERLINK("#'CH2. Tham số & Quy tắc'!B"&MATCH("slaOBT_hours",'CH2. Tham số & Quy tắc'!$A:$A,0),"CH2: slaOBT_hours") -> CH2: slaOBT_hours | H41: =HYPERLINK("#'CH4. Thông điệp nhắc việc'!C"&MATCH("NA010",'CH4. Thông điệp nhắc việc'!$A:$A,0),"CH4: NA010") -> CH4: NA010 | I41: =HYPERLINK("#'DL08. Xếp lớp & Nhập học'!Q4","Mở ô") -> Mở ô
...

Sheet CH1. Danh mục lựa chọn
A1: DANH MỤC LỰA CHỌN (ENUM)
A2: Đây là kho giá trị cho các ô dropdown (chọn từ danh sách) trong toàn file. Mỗi KHỐI là một danh mục (vd: nguồn lead, trạng thái lớp). Cột trái là MÃ kỹ thuật (tiếng Anh, dùng trong công thức), cột phải là giá trị hiển thị kèm nghĩa tiếng Việt. Muốn thêm/bớt lựa chọn cho một dropdown, sửa trong khối tương ứng ở đây - dropdown ở các sheet data sẽ tự cập nhật theo.
A3: Mã (kỹ thuật) | B3: Giá trị hiển thị (dropdown)
A4: lead_source - Nguồn lead
A5: Giá trị | B5: Combined (cho dropdown)
A6: facebook_ads | B6: facebook_ads (Quảng cáo Facebook)
A7: tiktok_ads | B7: tiktok_ads (Quảng cáo TikTok)
A8: website | B8: website (Form website ITTs)
A9: landing_page | B9: landing_page (Landing page chiến dịch)
A10: zalo_oa | B10: zalo_oa (Zalo Official Account)
A11: hotline | B11: hotline (Gọi đến hotline)
A12: walk_in | B12: walk_in (Khách tự đến trực tiếp)
A13: referral | B13: referral (Giới thiệu)
A14: seeding | B14: seeding (Bài seeding nội dung)
A15: upsell | B15: upsell (Học viên cũ mua thêm)
A16: other | B16: other (Khác)
A18: lead_qualification_status - Mức đủ điều kiện
A19: Giá trị | B19: Combined (cho dropdown)
A20: qualified | B20: qualified (Đủ điều kiện)
A21: unknown | B21: unknown (Chưa rõ)
A22: unqualified | B22: unqualified (Không phù hợp)
A24: lead_status - Trạng thái lead
A25: Giá trị | B25: Combined (cho dropdown)
A26: new | B26: new (Chưa liên hệ)
A27: contacted | B27: contacted (Đã liên hệ, đang khai thác)
A28: considering | B28: considering (Đang cân nhắc)
A29: no_response | B29: no_response (Không liên lạc được)
A30: unreachable | B30: unreachable (Hết cách liên lạc)
A31: rejected | B31: rejected (Từ chối)
A32: converted | B32: converted (Đã chuyển đổi - đã thành HV)
A34: contact_channel - Kênh liên hệ
A35: Giá trị | B35: Combined
A36: facebook | B36: facebook (Facebook)
A37: zalo | B37: zalo (Zalo)
A38: phone | B38: phone (Điện thoại)
A39: email | B39: email (Email)
A40: walk_in | B40: walk_in (Đến trực tiếp)
A41: other | B41: other (Khác)
A43: contact_direction - Chiều liên hệ
A44: Giá trị | B44: Combined
...

Sheet CH2. Tham số & Quy tắc
A1: THAM SỐ & QUY TẮC - CẤU HÌNH TẬP TRUNG (CONFIG-DRIVEN)
A2: Đây là nơi đặt các CON SỐ QUY TẮC của trung tâm (thời hạn xử lý/SLA, ngưỡng cảnh báo, định mức). Mỗi dòng là 1 tham số: cột "Value" là con số đang áp dụng (ô vàng = được phép sửa), cột "Mô tả" giải thích con số đó dùng làm gì. Ví dụ slaLRT_minutes=15 nghĩa là nhân viên tư vấn phải gọi lead mới trong vòng 15 phút. Khi bạn đổi con số ở đây, toàn bộ công thức/KPI/cảnh báo trong file tự tính lại theo - không cần sửa ở đâu khác.
A4: PHẦN 1 - PARAMETERS (sửa cột "Value" ô vàng để cấu hình)
A5: Param Name (named range) | B5: Value | C5: Unit | D5: Ý nghĩa (là gì) | E5: Mục đích (vì sao có) | F5: Giá trị đề xuất | G5: Ví dụ thực tế | H5: Tác động khi đổi & dùng ở đâu
A6: SLA THEO GIAI ĐOẠN (P1 - Lead ... P10 - Kết thúc khóa)
A7: slaLRT_minutes | B7: 15 | C7: phút | D7: Thời gian phản hồi lead mới (LRT): tối đa bao lâu phải gọi/nhắn 1 lead MỚI kể từ khi lead vào hệ thống. | E7: Không để lead nguội. Gọi càng sớm tỷ lệ chốt càng cao. | F7: 15 phút trong giờ làm việc. Nới 30 phút nếu ít người trực. | G7: Lead vào 9:00, đến 9:15 chưa gọi thì ô Việc cần làm ở DL02 hiện "Quá SLA LRT - GỌI NGAY". | H7: Đặt nhỏ hơn thì nhắc gắt hơn. Dùng ở DL02 (Khách tiềm năng), cột Việc cần làm.
A8: slaLeadReassign_hours | B8: 4 | C8: giờ | D8: Hạn giao lại lead cho NV khác nếu người được giao không gọi. | E8: Lead luôn có người chăm, không bị "ôm" rồi bỏ. | F8: 4 giờ. | G8: ="Lead đã giao cho NV nhưng quá "&$B$49&"h chưa gọi thì DL02 đề xuất giao NV khác." -> Lead đã giao cho NV nhưng quá 1000000h chưa gọi thì DL02 đề xuất giao NV khác. | H8: Đặt nhỏ hơn thì giao lại nhanh hơn. Dùng ở DL02 (Khách tiềm năng), cột Việc cần làm.
A9: slaGLA_hours | B9: 24 | C9: giờ | D9: Thời hạn chấm bài test đầu vào (GLA): tối đa bao lâu phải chấm xong bài test của khách. | E9: Trả kết quả test nhanh để kịp tư vấn, tránh khách chờ lâu rồi bỏ. | F9: 24 giờ. | G9: ="Khách làm test sáng nay, quá "&$B$8&"h chưa có điểm thì DL03 nhắc chấm." -> Khách làm test sáng nay, quá 4h chưa có điểm thì DL03 nhắc chấm. | H9: Nới ra thì khách chờ lâu hơn. Dùng ở DL03 (Đặt lịch test), cột Việc cần làm.
A10: slaCVT_hours | B10: 24 | C10: giờ | D10: Thời hạn tư vấn sau khi có kết quả test (CVT): có điểm rồi thì tối đa bao lâu phải tư vấn cho khách. | E10: Chốt khách khi còn quan tâm, ngay sau khi có kết quả. | F10: 24 giờ. | G10: ="Có điểm test lúc 10:00, quá "&$B$9&"h chưa tư vấn thì hệ thống nhắc tư vấn ngay." -> Có điểm test lúc 10:00, quá 24h chưa tư vấn thì hệ thống nhắc tư vấn ngay. | H10: Nới ra thì dễ mất khách. Dùng ở DL03/DL04, cột Việc cần làm.
A11: slaFollowup_grace_days | B11: 3 | C11: ngày | D11: Hạn theo dõi lại lead đang cân nhắc: quá số ngày này chưa liên hệ lại thì nhắc. | E11: Không bỏ quên lead còn quan tâm. | F11: 3 ngày. | G11: ="Lead ""đang cân nhắc"", quá "&$B$12&" ngày chưa gọi lại thì DL02 nhắc liên hệ." -> Lead "đang cân nhắc", quá 1 ngày chưa gọi lại thì DL02 nhắc liên hệ. | H11: Nới ra thì lead dễ nguội. Dùng ở DL02/DL04, cột Việc cần làm.
A12: slaApproval_days | B12: 1 | C12: ngày | D12: Hạn để cấp trên phê duyệt một yêu cầu (giảm giá, hoàn tiền...). | E12: Yêu cầu được duyệt nhanh, không tắc nghẽn. | F12: 1 ngày. | G12: ="Yêu cầu cần duyệt quá "&$B$59&" ngày chưa xử lý thì coi là trễ (tính vào KPI duyệt)." -> Yêu cầu cần duyệt quá ngày chưa xử lý thì coi là trễ (tính vào KPI duyệt). | H12: Nới ra thì duyệt chậm hơn. Dùng cho chỉ số tỷ lệ duyệt đúng hạn ở báo cáo.
A13: slaENR_pending_hours | B13: 24 | C13: giờ | D13: Hạn xử lý đăng ký đang chờ (pending): để chờ quá lâu thì nhắc xác nhận hoặc hủy. | E13: Không để đăng ký treo, chốt rõ xác nhận hay hủy. | F13: 24 giờ. | G13: ="Đăng ký để ""chờ"" quá "&$B$13&"h thì DL06 nhắc xác nhận/hủy." -> Đăng ký để "chờ" quá 24h thì DL06 nhắc xác nhận/hủy. | H13: Nới ra thì đăng ký treo lâu. Dùng ở DL06 (Đăng ký), cột Việc cần làm.
A14: slaENR_cancel_hours | B14: 72 | C14: giờ | D14: Hạn coi như hủy đăng ký: đăng ký "chờ" quá lâu thì đề xuất hủy hẳn. | E14: Dọn các đăng ký ảo, giải phóng chỗ. | F14: 72 giờ. | G14: ="Đăng ký ""chờ"" quá "&$B$14&"h thì DL06 báo ""cân nhắc HỦY đăng ký""." -> Đăng ký "chờ" quá 72h thì DL06 báo "cân nhắc HỦY đăng ký". | H14: Nới ra thì đăng ký ảo tồn lâu. Dùng ở DL06 (Đăng ký), cột Việc cần làm.
A15: slaPayment_grace_days | B15: 14 | C15: ngày | D15: Hạn trễ đóng đợt tiền tiếp theo: quá số ngày này chưa đóng thì nhắc/cảnh báo. | E15: Thu đủ học phí đúng hạn. | F15: 14 ngày. | G15: ="Còn nợ học phí, quá "&$B$15&" ngày kể từ hạn thì DL06 báo số tiền còn thiếu." -> Còn nợ học phí, quá 14 ngày kể từ hạn thì DL06 báo số tiền còn thiếu. | H15: Nới ra thì dòng tiền chậm. Dùng ở DL06/DL07, cột Việc cần làm.
A16: slaClassInfoZalo_hours | B16: 24 | C16: giờ | D16: Hạn gửi thông tin lớp qua Zalo cho HV sau khi xếp lớp. | E16: HV nhận thông tin lớp kịp thời để đi học đúng buổi đầu. | F16: 24 giờ. | G16: ="Đã xếp lớp nhưng quá "&$B$50&"h chưa gửi thông tin Zalo thì DL08 nhắc gửi." -> Đã xếp lớp nhưng quá 5000000h chưa gửi thông tin Zalo thì DL08 nhắc gửi. | H16: Nới ra thì HV nhận tin trễ. Dùng ở DL08 (Xếp lớp), cột Việc cần làm.
A17: slaPLR48_hours | B17: 48 | C17: giờ | D17: Thời hạn xếp lớp (PLR48): đăng ký đã xác nhận thì tối đa bao lâu phải xếp được lớp cho HV. | E17: Cho HV vào học sớm, không để chờ sau khi đã đóng tiền. | F17: 48 giờ. | G17: Đăng ký xác nhận thứ Hai, quá thứ Tư chưa xếp lớp thì DL08 báo "Quá PLR48 - XẾP LỚP NGAY". | H17: Nới ra thì HV chờ lâu hơn. Dùng ở DL08 (Xếp lớp), cột Việc cần làm.
A18: slaOBT_hours | B18: 72 | C18: giờ | D18: Thời hạn nhập học (OBT): tối đa bao lâu phải hoàn tất thủ tục nhập học cho HV. | E18: Hoàn tất onboarding để HV bắt đầu học đúng hẹn. | F18: 72 giờ. | G18: ="Đã xếp lớp nhưng quá "&$B$11&"h chưa hoàn tất nhập học thì hệ thống nhắc." -> Đã xếp lớp nhưng quá 3h chưa hoàn tất nhập học thì hệ thống nhắc. | H18: Nới ra thì onboarding chậm. Dùng ở DL08 (Xếp lớp), cột Việc cần làm.
A19: slaTeacherAttendance_minutes | B19: 30 | C19: phút | D19: Hạn để GV bắt đầu lớp/điểm danh sau giờ vào học. | E19: Đảm bảo lớp bắt đầu đúng giờ, có điểm danh. | F19: 30 phút. | G19: ="Quá "&$B$51&" phút sau giờ vào lớp mà buổi vẫn ""chưa bắt đầu"" thì DL11 nhắc kiểm tra GV." -> Quá 2 phút sau giờ vào lớp mà buổi vẫn "chưa bắt đầu" thì DL11 nhắc kiểm tra GV. | H19: Đặt nhỏ hơn thì siết giờ giấc GV chặt hơn. Dùng ở DL11 (Buổi học), cột Việc cần làm.
A20: slaTeacherNote_hours | B20: 48 | C20: giờ | D20: Thời hạn giáo viên ghi nhận xét buổi học (teacher_note) sau khi buổi kết thúc. | E20: Bảo đảm có nhận xét từng buổi để theo dõi tiến bộ HV. | F20: 48 giờ. | G20: ="Buổi xong quá "&$B$60&"h chưa ghi nhận xét thì DL11 nhắc ghi ngay." -> Buổi xong quá 4h chưa ghi nhận xét thì DL11 nhắc ghi ngay. | H20: Nới ra thì nhận xét buổi bị chậm. Dùng ở DL11 (Buổi học), cột Việc cần làm.
A21: slaAbsenceCall_hours | B21: 24 | C21: giờ | D21: Hạn gọi HV/phụ huynh sau buổi HV vắng không phép. | E21: Liên hệ ngay khi HV vắng để giữ HV không bỏ học. | F21: 24 giờ. | G21: ="HV vắng không phép, quá "&$B$52&"h chưa gọi thì DL12 báo ""GỌI HV/phụ huynh NGAY""." -> HV vắng không phép, quá 14h chưa gọi thì DL12 báo "GỌI HV/phụ huynh NGAY". | H21: Nới ra thì phản ứng chậm khi HV vắng. Dùng ở DL12 (Điểm danh), cột Việc cần làm.
A22: slaHomeworkGrading_hours | B22: 48 | C22: giờ | D22: Hạn GV chấm bài tập sau khi HV nộp. | E22: Trả bài nhanh để HV biết kết quả và sửa. | F22: 48 giờ. | G22: ="HV nộp bài, quá "&$B$53&"h chưa chấm thì DL13 báo ""Quá SLA chấm bài - CHẤM NGAY""." -> HV nộp bài, quá 30h chưa chấm thì DL13 báo "Quá SLA chấm bài - CHẤM NGAY". | H22: Đặt nhỏ hơn thì siết tốc độ chấm. Dùng ở DL13 (Bài tập), cột Việc cần làm.
A23: slaWowQuotaCheck_hours | B23: 24 | C23: giờ | D23: Hạn kiểm tra và trừ quota buổi WOW sau khi buổi kết thúc. | E23: Đảm bảo số buổi WOW được tính đúng, không lệch quota. | F23: 24 giờ. | G23: ="Buổi WOW xong quá "&$B$54&"h chưa trừ quota thì DL14 nhắc kiểm tra quota." -> Buổi WOW xong quá 90h chưa trừ quota thì DL14 nhắc kiểm tra quota. | H23: Nới ra thì quota dễ sai. Dùng ở DL14 (Buổi WOW 1-1), cột Việc cần làm.
A24: slaWowOutcomeRead_hours | B24: 24 | C24: giờ | D24: Hạn Học vụ đọc và ghi kết quả (content_note) buổi WOW. | E24: Nắm kết quả buổi kèm để theo dõi tiến bộ HV. | F24: 24 giờ. | G24: ="Buổi WOW xong quá "&$B$55&"h chưa ghi kết quả thì DL14 báo viết content_note ngay." -> Buổi WOW xong quá h chưa ghi kết quả thì DL14 báo viết content_note ngay. | H24: Nới ra thì theo dõi tiến bộ trễ. Dùng ở DL14 (Buổi WOW 1-1), cột Việc cần làm.
A25: slaSurveyReport_hours | B25: 48 | C25: giờ | D25: Hạn xử lý và báo cáo khảo sát sau khi HV nộp. | E25: Đọc phản hồi khảo sát kịp thời để cải thiện. | F25: 48 giờ. | G25: ="HV nộp khảo sát, quá "&$B$56&"h chưa xử lý thì DL15 nhắc phân công đọc và báo cáo." -> HV nộp khảo sát, quá 7h chưa xử lý thì DL15 nhắc phân công đọc và báo cáo. | H25: Nới ra thì phản hồi bị chậm xử lý. Dùng ở DL15 (Khảo sát), cột Việc cần làm.
A26: slaFB_classify_hours | B26: 24 | C26: giờ | D26: Hạn phân loại phản hồi mới (tích cực/tiêu cực/góp ý). | E26: Đọc và phân loại phản hồi kịp thời để hành động. | F26: 24 giờ. | G26: ="Phản hồi mới quá "&$B$21&"h chưa phân loại thì DL16 nhắc phân loại." -> Phản hồi mới quá 24h chưa phân loại thì DL16 nhắc phân loại. | H26: Nới ra thì phản hồi bị bỏ. Dùng ở DL16 (Phản hồi), quy trình xử lý.
A27: slaKN_assignment_hours | B27: 2 | C27: giờ | D27: Hạn phân công người xử lý cho khiếu nại MỚI. | E27: Khiếu nại có người phụ trách ngay, không bị bỏ. | F27: 2 giờ. | G27: ="Khiếu nại mới quá "&$B$17&"h chưa phân công thì DL17 báo ""Quá SLA phân công - GẤP""." -> Khiếu nại mới quá 48h chưa phân công thì DL17 báo "Quá SLA phân công - GẤP". | H27: Nới ra thì khiếu nại bị treo. Dùng ở DL17 (Khiếu nại), cột Việc cần làm.
A28: slaKN_high_hours | B28: 4 | C28: giờ | D28: Hạn xử lý khiếu nại mức độ cao. | E28: Việc nghiêm trọng được giải quyết nhanh. | F28: 4 giờ. | G28: ="Khiếu nại mức cao quá "&$B$18&"h chưa xử lý thì DL17 nhắc xử lý." -> Khiếu nại mức cao quá 72h chưa xử lý thì DL17 nhắc xử lý. | H28: Nới ra thì việc gấp bị chậm. Dùng ở DL17 (Khiếu nại), cột Việc cần làm.
A29: slaKN_medium_hours | B29: 48 | C29: giờ | D29: Hạn xử lý khiếu nại mức độ trung bình. | E29: Cân đối nguồn lực cho việc mức trung bình. | F29: 48 giờ. | G29: ="Khiếu nại mức trung bình quá "&$B$19&"h chưa xử lý thì DL17 nhắc." -> Khiếu nại mức trung bình quá 30h chưa xử lý thì DL17 nhắc. | H29: Nới ra thì tồn đọng nhiều. Dùng ở DL17 (Khiếu nại), cột Việc cần làm.
A30: slaKN_low_hours | B30: 168 | C30: giờ | D30: Hạn xử lý khiếu nại mức độ thấp. | E30: Việc nhỏ vẫn phải được phản hồi, không bỏ quên. | F30: 168 giờ (7 ngày). | G30: Khiếu nại mức thấp quá 7 ngày chưa xử lý thì DL17 báo cần phản hồi. | H30: Nới ra thì việc nhỏ tồn lâu. Dùng ở DL17 (Khiếu nại), cột Việc cần làm.
A31: slaActivity_inactive_days | B31: 7 | C31: ngày | D31: Số ngày HV không có hoạt động học thì coi là có nguy cơ. | E31: Phát hiện sớm HV bỏ học để can thiệp. | F31: 7 ngày. | G31: ="HV không có hoạt động học quá "&$B$16&" ngày thì DL09 báo ""Không activity quá SLA""." -> HV không có hoạt động học quá 24 ngày thì DL09 báo "Không activity quá SLA". | H31: Nới ra thì phát hiện trễ. Dùng ở DL09 (Học viên), cột Việc cần làm.
A32: slaFinalTest_days | B32: 3 | C32: ngày | D32: Hạn nhập điểm test cuối khóa sau khi HV hoàn thành. | E32: Có điểm cuối để đánh giá kết quả và tư vấn khóa tiếp. | F32: 3 ngày. | G32: ="HV hoàn thành khóa, quá "&$B$57&" ngày chưa có điểm test cuối thì DL18 nhắc nhập điểm." -> HV hoàn thành khóa, quá 14 ngày chưa có điểm test cuối thì DL18 nhắc nhập điểm. | H32: Nới ra thì đánh giá kết quả trễ. Dùng ở DL18 (Kết thúc khóa), cột Việc cần làm.
A33: slaReenroll_contact_days | B33: 3 | C33: ngày | D33: Hạn liên hệ tái ghi danh sau khi HV hoàn thành khóa. | E33: Giữ chân HV, mời học khóa tiếp theo đúng thời điểm. | F33: 3 ngày. | G33: ="HV hoàn thành khóa, quá "&$B$22&" ngày chưa liên hệ thì DL18 nhắc liên hệ tái ghi danh." -> HV hoàn thành khóa, quá 48 ngày chưa liên hệ thì DL18 nhắc liên hệ tái ghi danh. | H33: Nới ra thì bỏ lỡ cơ hội tái ghi danh. Dùng ở DL18 (Kết thúc khóa), cột Việc cần làm.
A34: slaReenrollSchedule_days | B34: 14 | C34: ngày | D34: Hạn chốt lịch khóa mới cho HV đã quan tâm tái ghi danh. | E34: Chuyển HV quan tâm thành đăng ký khóa mới kịp thời. | F34: 14 ngày. | G34: ="HV quan tâm tái ghi danh, quá "&$B$58&" ngày chưa xếp khóa thì DL18 nhắc chốt lịch." -> HV quan tâm tái ghi danh, quá 30 ngày chưa xếp khóa thì DL18 nhắc chốt lịch. | H34: Nới ra thì dễ mất HV quay lại. Dùng ở DL18 (Kết thúc khóa), cột Việc cần làm.
A35: slaQuote_days | B35: 1 | C35: ngày | D35: Hạn gửi báo giá sau buổi tư vấn. | E35: Khách còn nóng thì chốt nhanh, để lâu nguội. | F35: 1 ngày. | G35: Tư vấn hôm nay thì mai phải có báo giá. | H35: Hiển thị ở HD2 P3.
A36: slaPaymentConfirm_days | B36: 1 | C36: ngày | D36: Hạn gửi xác nhận/phiếu thu sau khi thu đủ tiền. | E36: Khách yên tâm đã đóng thành công. | F36: 1 ngày. | G36: Thu đủ hôm nay, mai gửi xác nhận. | H36: Hiển thị ở HD2 P4.
A37: slaRefundProcess_days | B37: 5 | C37: ngày | D37: Hạn hoàn tất chuyển tiền hoàn sau khi duyệt. | E37: Giữ uy tín khi HV rời đi. | F37: 5 ngày. | G37: Duyệt hoàn thứ 2 thì thứ 6 tiền phải về. | H37: Hiển thị ở HD2 P4.
A38: slaNoteReview_hours | B38: 24 | C38: giờ | D38: Hạn học vụ duyệt nhận xét buổi học của GV. | E38: Phát hiện sớm vấn đề trong note. | F38: 24 giờ. | G38: GV nộp note tối nay, trưa mai học vụ phải duyệt. | H38: Hiển thị ở HD2 P6.
A39: slaRiskFlagUpdate_hours | B39: 48 | C39: giờ | D39: Hạn cập nhật cờ nguy cơ sau chuỗi tín hiệu yếu. | E39: Cờ đúng lúc thì can thiệp đúng lúc. | F39: 48 giờ. | G39: HV yếu 3 buổi liền thì trong 2 ngày phải xét cờ. | H39: Hiển thị ở HD2 P6.
A40: slaWowBooking_hours | B40: 24 | C40: giờ | D40: Hạn xử lý/xác nhận một booking WOW (mọi nguồn đặt). | E40: Buổi WOW là cam kết chăm sóc - không để trôi. | F40: 24 giờ. | G40: HV tự đặt sáng nay, trong hôm sau phải chốt lịch. | H40: Hiển thị ở HD2 P7.
A41: slaSurveyCollect_days | B41: 7 | C41: ngày | D41: Hạn thu khảo sát định kỳ sau khi gửi form. | E41: Thu đủ phản hồi khi trải nghiệm còn mới. | F41: 7 ngày. | G41: Gửi form tuần 4 thì trong 7 ngày phải chốt số. | H41: Hiển thị ở HD2 P8.
...

Sheet CH3. Phân quyền
A1: BẢNG PHÂN QUYỀN VẬN HÀNH (Ai được làm gì)
A2: Bảng này quy định MỖI VAI TRÒ được làm những việc gì. Khi không chắc ai có quyền duyệt/xử lý một việc, tra ở đây. Việc nằm ngoài quyền của mình thì phải chuyển cho người có thẩm quyền (vd: duyệt chiết khấu lớn cần Trưởng phòng/CEO).
A3: Hành động | B3: NV Tư vấn (sales_staff) | C3: NV WOW (wow_coach) | D3: NV Học vụ (academic_staff) | E3: Giảng viên (teacher) | F3: Quản lý (các *_manager) | G3: Điều kiện áp dụng
A4: QUẢN LÝ LEAD & TƯ VẤN
A5: Nhập và tạo lead mới | B5: X | C5: X | G5: NV Tư vấn và NV WOW được nhập lead mới
A6: Cập nhật thông tin lead | B6: X | G6: NV Tư vấn chỉ sửa được lead mình phụ trách
A7: Đặt lịch test đầu vào | B7: X
A8: Bàn giao lead khi NV nghỉ đột xuất | F8: [duyệt] | G8: Quản lý phê duyệt khi bàn giao lead lúc nhân viên nghỉ
A9: QUẢN LÝ BUỔI TEST
A10: Điểm danh và giám sát buổi test | C10: X
A11: Chấm bài test, viết academic_note | C11: X | G11: Chỉ NV WOW được chấm bài test
